src/test/resources/sample_partial_message_ethusd.json
{
  "table": "orderBookL2",
  "action": "partial",
  "keys": [
    "symbol",
    "id",
    "side"
  ],
  "types": {
    "symbol": "symbol",
    "id": "long",
    "side": "symbol",
    "size": "long",
    "price": "float",
    "timestamp": "timestamp",
    "transactTime": "timestamp"
  },
  "filter": {
    "symbol": "ETHUSD"
  },
  "data": [
    {
      "symbol": "ETHUSD",
      "id": 1000188,
      "side": "Sell",
      "size": 1,
      "price": 21130.0,
      "timestamp": "2025-04-25T21:36:04.517Z",
      "transactTime": "2025-04-25T02:00:00.002Z"
    },
    {
      "symbol": "ETHUSD",
      "id": 12251526006,
      "side": "Sell",
      "size": 10,
      "price": 9366.8,
      "timestamp": "2025-04-25T21:36:04.517Z",
      "transactTime": "2025-04-25T02:00:00.002Z"
    },
    {
      "symbol": "ETHUSD",
      "id": 12251506972,
      "side": "Sell",
      "size": 10,
      "price": 8831.85,
      "timestamp": "2025-04-25T21:36:04.517Z",
      "transactTime": "2025-04-25T02:00:00.002Z"
    },
    {
      "symbol": "ETHUSD",
      "id": 21785086342,
      "side": "Sell",
      "size": 5,
      "price": 8252.15,
      "timestamp": "2025-04-25T21:36:04.517Z",
      "transactTime": "2025-04-25T02:00:00.002Z"
    },
    {
      "symbol": "ETHUSD",
      "id": 1000218,
      "side": "Sell",
      "size": 1,
      "price": 8024.0,
      "timestamp": "2025-04-25T21:36:04.517Z",
      "transactTime": "2025-04-25T02:00:00.002Z"
    },
    {
      "symbol": "ETHUSD",
      "id": 21785093041,
      "side": "Sell",
      "size": 5,
      "price": 7537.15,
      "timestamp": "2025-04-25T21:36:04.517Z",
      "transactTime": "2025-04-25T02:00:00.002Z"
    },
    {
      "symbol": "ETHUSD",
      "id": 72149823072,
      "side": "Sell",
      "size": 200,
      "price": 7248.54,
      "timestamp": "2025-04-25T21:36:04.517Z",
      "transactTime": "2025-04-25T02:00:00.002Z"
    },
    {
      "symbol": "ETHUSD",
      "id": 63191013936,
      "side": "Sell",
      "size": 33,
      "price": 7000.0,
      "timestamp": "2025-04-25T21:36:04.517Z",
      "transactTime": "2025-04-25T02:00:00.002Z"
    },
    {
      "symbol": "ETHUSD",
      "id": 61765492156,
      "side": "Sell",
      "size": 10,
      "price": 6999.0,
      "timestamp": "2025-04-25T21:36:04.517Z",
      "transactTime": "2025-04-25T02:00:00.002Z"
    },
    {
      "symbol": "ETHUSD",
      "id": 72149824890,
      "side": "Sell",
      "size": 200,
      "price": 6708.49,
      "timestamp": "2025-04-25T21:36:04.517Z",
      "transactTime": "2025-04-25T02:00:00.002Z"
    },
    {
      "symbol": "ETHUSD",
      "id": 72149826338,
      "side": "Sell",
      "size": 100,
      "price": 6173.17,
      "timestamp": "2025-04-25T21:36:04.517Z",
      "transactTime": "2025-04-25T02:00:00.002Z"
    },
    {
      "symbol": "ETHUSD",
      "id": 72149827927,
      "side": "Sell",
      "size": 100,
      "price": 5648.08,
      "timestamp": "2025-04-25T21:36:04.517Z",
      "transactTime": "2025-04-25T02:00:00.002Z"
    },
    {
      "symbol": "ETHUSD",
      "id": 81149144465,
      "side": "Sell",
      "size": 1,
      "price": 5500.0,
      "timestamp": "2025-04-25T21:36:04.517Z",
      "transactTime": "2025-04-25T02:00:00.002Z"
    },
    {
      "symbol": "ETHUSD",
      "id": 72676316274,
      "side": "Sell",
      "size": 200,
      "price": 5461.23,
      "timestamp": "2025-04-25T21:36:04.517Z",
      "transactTime": "2025-04-25T02:00:00.002Z"
    },
    {
      "symbol": "ETHUSD",
      "id": 61765173809,
      "side": "Sell",
      "size": 3,
      "price": 5300.0,
      "timestamp": "2025-04-25T21:36:04.517Z",
      "transactTime": "2025-04-25T02:00:00.002Z"
    },
    {
      "symbol": "ETHUSD",
      "id": 1000485,
      "side": "Sell",
      "size": 1,
      "price": 5170.05,
      "timestamp": "2025-04-25T21:36:04.517Z",
      "transactTime": "2025-04-25T02:00:00.002Z"
    },
    {
      "symbol": "ETHUSD",
      "id": 23415473046,
      "side": "Sell",
      "size": 1,
      "price": 5010.0,
      "timestamp": "2025-04-25T21:36:04.517Z",
      "transactTime": "2025-04-25T02:00:00.002Z"
    },
    {
      "symbol": "ETHUSD",
      "id": 23415451712,
      "side": "Sell",
      "size": 1,
      "price": 4975.0,
      "timestamp": "2025-04-25T21:36:04.517Z",
      "transactTime": "2025-04-25T02:00:00.002Z"
    },
    {
      "symbol": "ETHUSD",
      "id": 82959608614,
      "side": "Sell",
      "size": 2,
      "price": 4942.31,
      "timestamp": "2025-04-25T21:36:04.517Z",
      "transactTime": "2025-04-25T02:00:00.002Z"
    },
    {
      "symbol": "ETHUSD",
      "id": 23415434598,
      "side": "Sell",
      "size": 1,
      "price": 4940.0,
      "timestamp": "2025-04-25T21:36:04.517Z",
      "transactTime": "2025-04-25T02:00:00.002Z"
    },
    {
      "symbol": "ETHUSD",
      "id": 23415419748,
      "side": "Sell",
      "size": 1,
      "price": 4905.0,
      "timestamp": "2025-04-25T21:36:04.517Z",
      "transactTime": "2025-04-25T02:00:00.002Z"
    },
    {
      "symbol": "ETHUSD",
      "id": 23415398513,
      "side": "Sell",
      "size": 1,
      "price": 4870.0,
      "timestamp": "2025-04-25T21:36:04.517Z",
      "transactTime": "2025-04-25T02:00:00.002Z"
    },
    {
      "symbol": "ETHUSD",
      "id": 23427626264,
      "side": "Sell",
      "size": 5,
      "price": 4850.0,
      "timestamp": "2025-04-25T21:36:04.517Z",
      "transactTime": "2025-04-25T02:00:00.002Z"
    },
    {
      "symbol": "ETHUSD",
      "id": 23415385863,
      "side": "Sell",
      "size": 1,
      "price": 4835.0,
      "timestamp": "2025-04-25T21:36:04.517Z",
      "transactTime": "2025-04-25T02:00:00.002Z"
    },
    {
      "symbol": "ETHUSD",
      "id": 65147900001,
      "side": "Sell",
      "size": 5,
      "price": 4808.81,
      "timestamp": "2025-04-25T21:36:04.517Z",
      "transactTime": "2025-04-25T02:00:00.002Z"
    },
    {
      "symbol": "ETHUSD",
      "id": 1001019,
      "side": "Sell",
      "size": 2,
      "price": 4800.0,
      "timestamp": "2025-04-25T21:36:04.517Z",
      "transactTime": "2025-04-25T02:00:00.002Z"
    },
    {
      "symbol": "ETHUSD",
      "id": 23415335533,
      "side": "Sell",
      "size": 1,
      "price": 4765.0,
      "timestamp": "2025-04-25T21:36:04.517Z",
      "transactTime": "2025-04-25T02:00:00.002Z"
    },
    {
      "symbol": "ETHUSD",
      "id": 23415324754,
      "side": "Sell",
      "size": 1,
      "price": 4730.0,
      "timestamp": "2025-04-25T21:36:04.517Z",
      "transactTime": "2025-04-25T02:00:00.002Z"
    },
    {
      "symbol": "ETHUSD",
      "id": 65147911364,
      "side": "Sell",
      "size": 5,
      "price": 4699.04,
      "timestamp": "2025-04-25T21:36:04.517Z",
      "transactTime": "2025-04-25T02:00:00.002Z"
    },
    {
      "symbol": "ETHUSD",
      "id": 23415304480,
      "side": "Sell",
      "size": 1,
      "price": 4695.0,
      "timestamp": "2025-04-25T21:36:04.517Z",
      "transactTime": "2025-04-25T02:00:00.002Z"
    },
    {
      "symbol": "ETHUSD",
      "id": 1001015,
      "side": "Sell",
      "size": 912,
      "price": 4679.0,
      "timestamp": "2025-04-25T21:36:04.517Z",
      "transactTime": "2025-04-25T02:00:00.002Z"
    },
    {
      "symbol": "ETHUSD",
      "id": 21613965966,
      "side": "Sell",
      "size": 55,
      "price": 4670.65,
      "timestamp": "2025-04-25T21:36:04.517Z",
      "transactTime": "2025-04-25T02:00:00.002Z"
    },
    {
      "symbol": "ETHUSD",
      "id": 23415287496,
      "side": "Sell",
      "size": 1,
      "price": 4660.0,
      "timestamp": "2025-04-25T21:36:04.517Z",
      "transactTime": "2025-04-25T02:00:00.002Z"
    },
    {
      "symbol": "ETHUSD",
      "id": 67605137782,
      "side": "Sell",
      "size": 200,
      "price": 4630.0,
      "timestamp": "2025-04-25T21:36:04.517Z",
      "transactTime": "2025-04-25T02:00:00.002Z"
    },
    {
      "symbol": "ETHUSD",
      "id": 23415262927,
      "side": "Sell",
      "size": 1,
      "price": 4625.0,
