src/test/resources/sample_partial_message_xbtusd.json
{
  "table": "orderBookL2",
  "action": "partial",
  "keys": [
    "symbol",
    "id",
    "side"
  ],
  "types": {
    "symbol": "symbol",
    "id": "long",
    "side": "symbol",
    "size": "long",
    "price": "float",
    "timestamp": "timestamp",
    "transactTime": "timestamp"
  },
  "filter": {
    "symbol": "XBTUSD"
  },
  "data": [
    {
      "symbol": "XBTUSD",
      "id": 17180110699,
      "side": "Sell",
      "size": 900,
      "price": 3201030.0,
      "timestamp": "2025-04-25T21:18:20.859Z",
      "transactTime": "2025-04-25T02:00:00.002Z"
    },
    {
      "symbol": "XBTUSD",
      "id": 1000330,
      "side": "Sell",
      "size": 1000000,
      "price": 1000000.0,
      "timestamp": "2025-04-25T21:18:20.859Z",
      "transactTime": "2025-04-25T02:00:00.002Z"
    },
    {
      "symbol": "XBTUSD",
      "id": 25039222234,
      "side": "Sell",
      "size": 33800,
      "price": 676700.0,
      "timestamp": "2025-04-25T21:18:20.859Z",
      "transactTime": "2025-04-25T02:00:00.002Z"
    },
    {
      "symbol": "XBTUSD",
      "id": 1000294,
      "side": "Sell",
      "size": 10000,
      "price": 662520.0,
      "timestamp": "2025-04-25T21:18:20.859Z",
      "transactTime": "2025-04-25T02:00:00.002Z"
    },
    {
      "symbol": "XBTUSD",
      "id": 1000193,
      "side": "Sell",
      "size": 20000,
      "price": 658900.0,
      "timestamp": "2025-04-25T21:18:20.859Z",
      "transactTime": "2025-04-25T02:00:00.002Z"
    },
    {
      "symbol": "XBTUSD",
      "id": 1000340,
      "side": "Sell",
      "size": 10000,
      "price": 657700.0,
      "timestamp": "2025-04-25T21:18:20.859Z",
      "transactTime": "2025-04-25T02:00:00.002Z"
    },
    {
      "symbol": "XBTUSD",
      "id": 13610125739,
      "side": "Sell",
      "size": 50000,
      "price": 500000.0,
      "timestamp": "2025-04-25T21:18:20.859Z",
      "transactTime": "2025-04-25T02:00:00.002Z"
    },
    {
      "symbol": "XBTUSD",
      "id": 1000727,
      "side": "Sell",
      "size": 100,
      "price": 488104.0,
      "timestamp": "2025-04-25T21:18:20.859Z",
      "transactTime": "2025-04-25T02:00:00.002Z"
    },
    {
      "symbol": "XBTUSD",
      "id": 1000179,
      "side": "Sell",
      "size": 100,
      "price": 393400.0,
      "timestamp": "2025-04-25T21:18:20.859Z",
      "transactTime": "2025-04-25T02:00:00.002Z"
    },
    {
      "symbol": "XBTUSD",
      "id": 1000170,
      "side": "Sell",
      "size": 1000,
      "price": 351500.5,
      "timestamp": "2025-04-25T21:18:20.859Z",
      "transactTime": "2025-04-25T02:00:00.002Z"
    },
    {
      "symbol": "XBTUSD",
      "id": 65612414096,
      "side": "Sell",
      "size": 100,
      "price": 350000.0,
      "timestamp": "2025-04-25T21:18:20.859Z",
      "transactTime": "2025-04-25T02:00:00.002Z"
    },
    {
      "symbol": "XBTUSD",
      "id": 1000175,
      "side": "Sell",
      "size": 100,
      "price": 333670.0,
      "timestamp": "2025-04-25T21:18:20.859Z",
      "transactTime": "2025-04-25T02:00:00.002Z"
    },
    {
      "symbol": "XBTUSD",
      "id": 78866429972,
      "side": "Sell",
      "size": 100,
      "price": 305144.5,
      "timestamp": "2025-04-25T21:18:20.859Z",
      "transactTime": "2025-04-25T02:00:00.002Z"
    },
    {
      "symbol": "XBTUSD",
      "id": 78866428680,
      "side": "Sell",
      "size": 100,
      "price": 304383.6,
      "timestamp": "2025-04-25T21:18:20.859Z",
      "transactTime": "2025-04-25T02:00:00.002Z"
    },
    {
      "symbol": "XBTUSD",
      "id": 65612394922,
      "side": "Sell",
      "size": 100,
      "price": 300000.0,
      "timestamp": "2025-04-25T21:18:20.859Z",
      "transactTime": "2025-04-25T02:00:00.002Z"
    },
    {
      "symbol": "XBTUSD",
      "id": 90470320622,
      "side": "Sell",
      "size": 1600,
      "price": 286408.9,
      "timestamp": "2025-04-25T21:18:20.859Z",
      "transactTime": "2025-04-25T02:00:00.002Z"
    },
    {
      "symbol": "XBTUSD",
      "id": 59092140323,
      "side": "Sell",
      "size": 2000,
      "price": 250501.3,
      "timestamp": "2025-04-25T21:18:20.859Z",
      "transactTime": "2025-04-25T02:00:00.002Z"
    },
    {
      "symbol": "XBTUSD",
      "id": 65418575139,
      "side": "Sell",
      "size": 100,
      "price": 250000.0,
      "timestamp": "2025-04-25T21:18:20.859Z",
      "transactTime": "2025-04-25T02:00:00.002Z"
    },
    {
      "symbol": "XBTUSD",
      "id": 1000151,
      "side": "Sell",
      "size": 100,
      "price": 233653.5,
      "timestamp": "2025-04-25T21:18:20.859Z",
      "transactTime": "2025-04-25T02:00:00.002Z"
    },
    {
      "symbol": "XBTUSD",
      "id": 63969965369,
      "side": "Sell",
      "size": 5000,
      "price": 221000.0,
      "timestamp": "2025-04-25T21:18:20.859Z",
      "transactTime": "2025-04-25T02:00:00.002Z"
    },
    {
      "symbol": "XBTUSD",
      "id": 59092248991,
      "side": "Sell",
      "size": 500,
      "price": 200240.0,
      "timestamp": "2025-04-25T21:18:20.859Z",
      "transactTime": "2025-04-25T02:00:00.002Z"
    },
    {
      "symbol": "XBTUSD",
      "id": 1002134,
      "side": "Sell",
      "size": 50100,
      "price": 200000.0,
      "timestamp": "2025-04-25T21:18:20.859Z",
      "transactTime": "2025-04-25T02:00:00.002Z"
    },
    {
      "symbol": "XBTUSD",
      "id": 82702363766,
      "side": "Sell",
      "size": 100,
      "price": 190000.0,
      "timestamp": "2025-04-25T21:18:20.859Z",
      "transactTime": "2025-04-25T02:00:00.002Z"
    },
    {
      "symbol": "XBTUSD",
      "id": 1000142,
      "side": "Sell",
      "size": 10000,
      "price": 189175.0,
      "timestamp": "2025-04-25T21:18:20.859Z",
      "transactTime": "2025-04-25T02:00:00.002Z"
    },
    {
      "symbol": "XBTUSD",
      "id": 84778173357,
      "side": "Sell",
      "size": 600,
      "price": 184000.4,
      "timestamp": "2025-04-25T21:18:20.859Z",
      "transactTime": "2025-04-25T02:00:00.002Z"
    },
    {
      "symbol": "XBTUSD",
      "id": 35687224457,
      "side": "Sell",
      "size": 200,
      "price": 183000.0,
      "timestamp": "2025-04-25T21:18:20.859Z",
      "transactTime": "2025-04-25T02:00:00.002Z"
    },
    {
      "symbol": "XBTUSD",
      "id": 35457026692,
      "side": "Sell",
      "size": 200,
      "price": 182000.0,
      "timestamp": "2025-04-25T21:18:20.859Z",
      "transactTime": "2025-04-25T02:00:00.002Z"
    },
    {
      "symbol": "XBTUSD",
      "id": 35236838964,
      "side": "Sell",
      "size": 200,
      "price": 181000.0,
      "timestamp": "2025-04-25T21:18:20.859Z",
      "transactTime": "2025-04-25T02:00:00.002Z"
    },
    {
      "symbol": "XBTUSD",
      "id": 1000806,
      "side": "Sell",
      "size": 100,
      "price": 180000.0,
      "timestamp": "2025-04-25T21:18:20.859Z",
      "transactTime": "2025-04-25T02:00:00.002Z"
    },
    {
      "symbol": "XBTUSD",
      "id": 1000807,
      "side": "Sell",
      "size": 100,
      "price": 179000.0,
      "timestamp": "2025-04-25T21:18:20.859Z",
      "transactTime": "2025-04-25T02:00:00.002Z"
    },
    {
      "symbol": "XBTUSD",
      "id": 73152878947,
      "side": "Sell",
      "size": 250000,
      "price": 178988.8,
      "timestamp": "2025-04-25T21:18:20.859Z",
      "transactTime": "2025-04-25T02:00:00.002Z"
    },
    {
      "symbol": "XBTUSD",
      "id": 1000808,
      "side": "Sell",
      "size": 100,
      "price": 178000.0,
      "timestamp": "2025-04-25T21:18:20.859Z",
      "transactTime": "2025-04-25T02:00:00.002Z"
    },
    {
      "symbol": "XBTUSD",
      "id": 1000810,
      "side": "Sell",
      "size": 100,
      "price": 177000.5,
      "timestamp": "2025-04-25T21:18:20.859Z",
      "transactTime": "2025-04-25T02:00:00.002Z"
    },
    {
      "symbol": "XBTUSD",
      "id": 1000811,
      "side": "Sell",
      "size": 100,
      "price": 176000.5,
      "timestamp": "2025-04-25T21:18:20.859Z",
      "transactTime": "2025-04-25T02:00:00.002Z"
    },
    {
      "symbol": "XBTUSD",
